<?xml version="1.0" encoding="utf-8"?>
<!-- This URDF was automatically created by SolidWorks to URDF Exporter! Originally created by Stephen Brawner (brawner@gmail.com) 
     Commit Version: 1.6.0-4-g7f85cfe  Build Version: 1.6.7995.38578
     For more information, please see http://wiki.ros.org/sw_urdf_exporter -->
<robot
  name="full_sampling_urdf">
  <link name="world"/>
  <joint name="base_rover" type="fixed">
      <parent link="world"/>
      <child link="rover"/>
      <origin rpy="0 0 0" xyz="0.0 0.0 0.00001"/>
  </joint>
  <link
    name="rover">
    <inertial>
      <origin
        xyz="-0.029777 -0.04233 0.22201"
        rpy="0 0 0" />
      <mass
        value="23.83" />
      <inertia
        ixx="0.10672"
        ixy="-0.0004091"
        ixz="-0.0028185"
        iyy="0.13598"
        iyz="-0.0022915"
        izz="0.14333" />
    </inertial>
    <visual>
      <origin
        xyz="0 0 0"
        rpy="0 0 0" />
      <geometry>
        <mesh
          filename="package://full_sampling_urdf/meshes/rover.STL" />
      </geometry>
      <material
        name="">
        <color
          rgba="0.79216 0.81961 0.93333 1" />
      </material>
    </visual>
    <collision>
      <origin
        xyz="0 0 0"
        rpy="0 0 0" />
      <geometry>
        <mesh
          filename="package://full_sampling_urdf/meshes/rover.STL" />
      </geometry>
    </collision>
  </link>
  <link
    name="base_arm">
    <inertial>
      <origin
        xyz="-4.0327E-09 -1.0227E-07 0.053561"
        rpy="0 0 0" />
      <mass
        value="1.1556" />
      <inertia
        ixx="0.0056425"
        ixy="-2.1507E-18"
        ixz="2.1873E-18"
        iyy="0.0056425"
        iyz="-3.0773E-17"
        izz="0.0078318" />
    </inertial>
    <visual>
      <origin
        xyz="0 0 0"
        rpy="0 0 0" />
      <geometry>
        <mesh
          filename="package://full_sampling_urdf/meshes/base_arm.STL" />
      </geometry>
      <material
        name="">
        <color
          rgba="0.79216 0.81961 0.93333 1" />
      </material>
    </visual>
    <collision>
      <origin
        xyz="0 0 0"
        rpy="0 0 0" />
      <geometry>
        <mesh
          filename="package://full_sampling_urdf/meshes/base_arm.STL" />
      </geometry>
    </collision>
  </link>
  <joint
    name="base_joint"
    type="fixed">
    <origin
      xyz="0.24899 0.00070869 0.407"
      rpy="0 0 0" />
    <parent
      link="rover" />
    <child
      link="base_arm" />
    <axis
      xyz="0 0 0" />
  </joint>
  <link
    name="link_1">
    <inertial>
      <origin
        xyz="-0.01406 0.00054755 0.076994"
        rpy="0 0 0" />
      <mass
        value="0.68744" />
      <inertia
        ixx="0.0012842"
        ixy="9.1195E-07"
        ixz="-0.00011108"
        iyy="0.0019828"
        iyz="-6.3597E-06"
        izz="0.0013733" />
    </inertial>
    <visual>
      <origin
        xyz="0 0 0"
        rpy="0 0 0" />
      <geometry>
        <mesh
          filename="package://full_sampling_urdf/meshes/link_1.STL" />
      </geometry>
      <material
        name="">
        <color
          rgba="0.89804 0.91765 0.92941 1" />
      </material>
    </visual>
    <collision>
      <origin
        xyz="0 0 0"
        rpy="0 0 0" />
      <geometry>
        <mesh
          filename="package://full_sampling_urdf/meshes/link_1.STL" />
      </geometry>
    </collision>
  </link>
  <joint
    name="joint_1"
    type="revolute">
    <origin
      xyz="0 0 0.133"
      rpy="0 0 0" />
    <parent
      link="base_arm" />
    <child
      link="link_1" />
    <axis
      xyz="0 0 1" />
    <limit
      lower="-3.14"
      upper="3.14"
      effort="100"
      velocity="2" />
  </joint>
  <link
    name="link_2">
    <inertial>
      <origin
        xyz="-0.00045755 0.40328 0.043283"
        rpy="0 0 0" />
      <mass
        value="0.4979" />
      <inertia
        ixx="0.0016855"
        ixy="5.5179E-06"
        ixz="8.2239E-07"
        iyy="0.0004916"
        iyz="-3.1358E-05"
        izz="0.0016038" />
    </inertial>
    <visual>
      <origin
        xyz="0 0 0"
        rpy="0 0 0" />
      <geometry>
        <mesh
          filename="package://full_sampling_urdf/meshes/link_2.STL" />
      </geometry>
      <material
        name="">
        <color
          rgba="0.79216 0.81961 0.93333 1" />
      </material>
    </visual>
    <collision>
      <origin
        xyz="0 0 0"
        rpy="0 0 0" />
      <geometry>
        <mesh
          filename="package://full_sampling_urdf/meshes/link_2.STL" />
      </geometry>
    </collision>
  </link>
  <joint
    name="joint_2"
    type="revolute">
    <origin
      xyz="0.035502 0 0.1489"
      rpy="1.6351 -1.0672 -0.073404" />
    <parent
      link="link_1" />
    <child
      link="link_2" />
    <axis
      xyz="-0.035393 0 -0.99937" />
    <limit
      lower="0"
      upper="4.71"
      effort="100"
      velocity="2" />
  </joint>
  <link
    name="link_3">
    <inertial>
      <origin
        xyz="-0.000291 -0.019482 0.039042"
        rpy="0 0 0" />
      <mass
        value="0.7923" />
      <inertia
        ixx="0.0012569"
        ixy="-2.4571E-06"
        ixz="4.6665E-06"
        iyy="0.001197"
        iyz="2.0351E-05"
        izz="0.0014787" />
    </inertial>
    <visual>
      <origin
        xyz="0 0 0"
        rpy="0 0 0" />
      <geometry>
        <mesh
          filename="package://full_sampling_urdf/meshes/link_3.STL" />
      </geometry>
      <material
        name="">
        <color
          rgba="0.79216 0.81961 0.93333 1" />
      </material>
    </visual>
    <collision>
      <origin
        xyz="0 0 0"
        rpy="0 0 0" />
      <geometry>
        <mesh
          filename="package://full_sampling_urdf/meshes/link_3.STL" />
      </geometry>
    </collision>
  </link>
  <joint
    name="joint_3"
    type="revolute">
    <origin
      xyz="0 0.5275 0.1315"
      rpy="0 0 -1.0686" />
    <parent
      link="link_2" />
    <child
      link="link_3" />
    <axis
      xyz="0 0 -1" />
    <limit
      lower="0"
      upper="6.28"
      effort="50"
      velocity="4" />
  </joint>
  <link
    name="link_4">
    <inertial>
      <origin
        xyz="0.00050132 0.0079397 0.021739"
        rpy="0 0 0" />
      <mass
        value="0.66623" />
      <inertia
        ixx="0.00088572"
        ixy="-1.7903E-06"
        ixz="4.2323E-06"
        iyy="0.00090613"
        iyz="-1.458E-05"
        izz="0.0011479" />
    </inertial>
    <visual>
      <origin
        xyz="0 0 0"
        rpy="0 0 0" />
      <geometry>
        <mesh
          filename="package://full_sampling_urdf/meshes/link_4.STL" />
      </geometry>
      <material
        name="">
        <color
          rgba="0.79216 0.81961 0.93333 1" />
      </material>
    </visual>
    <collision>
      <origin
        xyz="0 0 0"
        rpy="0 0 0" />
      <geometry>
        <mesh
          filename="package://full_sampling_urdf/meshes/link_4.STL" />
      </geometry>
    </collision>
  </link>
  <joint
    name="joint_4"
    type="revolute">
    <origin
      xyz="6.8566E-05 -0.12961 0.10761"
      rpy="-0.50301 1.5354 -2.073" />
    <parent
      link="link_3" />
    <child
      link="link_4" />
    <axis
      xyz="-0.031013 0 -0.99952" />
    <limit
      lower="0"
      upper="6.28"
      effort="50"
      velocity="4" />
  </joint>
  <link
    name="link_5">
    <inertial>
      <origin
        xyz="8.5395E-05 0.0195 0.015426"
        rpy="0 0 0" />
      <mass
        value="0.072706" />
      <inertia
        ixx="9.5574E-05"
        ixy="-2.287E-08"
        ixz="2.2014E-09"
        iyy="8.2533E-05"
        iyz="-6.206E-06"
        izz="0.00016181" />
    </inertial>
    <visual>
      <origin
        xyz="0 0 0"
        rpy="0 0 0" />
      <geometry>
        <mesh
          filename="package://full_sampling_urdf/meshes/link_5.STL" />
      </geometry>
      <material
        name="">
        <color
          rgba="0.69804 0.69804 0.69804 1" />
      </material>
    </visual>
    <collision>
      <origin
        xyz="0 0 0"
        rpy="0 0 0" />
      <geometry>
        <mesh
          filename="package://full_sampling_urdf/meshes/link_5.STL" />
      </geometry>
    </collision>
  </link>
  <joint
    name="joint_5"
    type="revolute">
    <origin
      xyz="-0.0010256 0.083 0.10269"
      rpy="-1.5692 0.030978 0.050701" />
    <parent
      link="link_4" />
    <child
      link="link_5" />
    <axis
      xyz="0 0 -1" />
    <limit
      lower="-3.14"
      upper="3.14"
      effort="50"
      velocity="4" />
  </joint>
  <link
    name="link_6">
    <inertial>
      <origin
        xyz="-0.0017604 0.062158 -0.17532"
        rpy="0 0 0" />
      <mass
        value="0.14212" />
      <inertia
        ixx="0.00013968"
        ixy="3.672E-07"
        ixz="-4.6714E-08"
        iyy="0.00027464"
        iyz="-8.9751E-07"
        izz="0.00017205" />
    </inertial>
    <visual>
      <origin
        xyz="0 0 0"
        rpy="0 0 0" />
      <geometry>
        <mesh
          filename="package://full_sampling_urdf/meshes/link_6.STL" />
      </geometry>
      <material
        name="">
        <color
          rgba="0.79216 0.81961 0.93333 1" />
      </material>
    </visual>
    <collision>
      <origin
        xyz="0 0 0"
        rpy="0 0 0" />
      <geometry>
        <mesh
          filename="package://full_sampling_urdf/meshes/link_6.STL" />
      </geometry>
    </collision>
  </link>
  <joint
    name="joint_6"
    type="fixed">
    <origin
      xyz="0 -0.050661 0.25285"
      rpy="0 0 -0.010445" />
    <parent
      link="link_5" />
    <child
      link="link_6" />
    <axis
      xyz="0 0 0" />
  </joint>
  <link
    name="Right_ee">
    <inertial>
      <origin
        xyz="-0.0074213 0.15375 0.039993"
        rpy="0 0 0" />
      <mass
        value="0.12335" />
      <inertia
        ixx="0.00024213"
        ixy="1.1333E-06"
        ixz="4.9689E-07"
        iyy="0.00013613"
        iyz="-2.9952E-06"
        izz="0.00016427" />
    </inertial>
    <visual>
      <origin
        xyz="0 0 0"
        rpy="0 0 0" />
      <geometry>
        <mesh
          filename="package://full_sampling_urdf/meshes/Right_ee.STL" />
      </geometry>
      <material
        name="">
        <color
          rgba="0.77647 0.75686 0.73725 1" />
      </material>
    </visual>
    <collision>
      <origin
        xyz="0 0 0"
        rpy="0 0 0" />
      <geometry>
        <mesh
          filename="package://full_sampling_urdf/meshes/Right_ee.STL" />
      </geometry>
    </collision>
  </link>
  <joint
    name="joint_ree"
    type="revolute">
    <origin
      xyz="-0.030503 0.047545 -0.18085"
      rpy="1.5692 0.050652 -0.020613" />
    <parent
      link="link_6" />
    <child
      link="Right_ee" />
    <axis
      xyz="0.031013 0 0.99952" />
    <limit
      lower="0"
      upper="0.8"
      effort="15"
      velocity="1" />
  </joint>
  <link
    name="Left_ee">
    <inertial>
      <origin
        xyz="0.0046963 0.15434 -0.039694"
        rpy="0 0 0" />
      <mass
        value="0.12478" />
      <inertia
        ixx="0.00024869"
        ixy="-9.1851E-06"
        ixz="-6.3585E-06"
        iyy="0.00014314"
        iyz="4.4771E-06"
        izz="0.00016894" />
    </inertial>
    <visual>
      <origin
        xyz="0 0 0"
        rpy="0 0 0" />
      <geometry>
        <mesh
          filename="package://full_sampling_urdf/meshes/Left_ee.STL" />
      </geometry>
      <material
        name="">
        <color
          rgba="0.77647 0.75686 0.73725 1" />
      </material>
    </visual>
    <collision>
      <origin
        xyz="0 0 0"
        rpy="0 0 0" />
      <geometry>
        <mesh
          filename="package://full_sampling_urdf/meshes/Left_ee.STL" />
      </geometry>
    </collision>
  </link>
  <joint
    name="joint_lee"
    type="revolute">
    <origin
      xyz="0.029494 0.048172 -0.18085"
      rpy="1.5724 -0.050652 3.121" />
    <parent
      link="link_6" />
    <child
      link="Left_ee" />
    <axis
      xyz="0.031013 0 0.99952" />
    <limit
      lower="0"
      upper="0.8"
      effort="15"
      velocity="1" />
  </joint>

  <transmission name="link_1_trans">
        <type>transmission_interface/SimpleTransmission</type>
        <joint name="joint_1">
              <hardwareInterface>hardware_interface/PositionJointInterface</hardwareInterface> 
        </joint>
        <actuator name="link_1_motor">
              <hardwareInterface>hardware_interface/PositionJointInterface</hardwareInterface> 
              <mechanicalReduction>1</mechanicalReduction>
        </actuator>
  </transmission>

  <transmission name="link_2_trans">
        <type>transmission_interface/SimpleTransmission</type>
        <joint name="joint_2">
              <hardwareInterface>hardware_interface/PositionJointInterface</hardwareInterface> 
        </joint>
        <actuator name="link_2_motor">
              <hardwareInterface>hardware_interface/PositionJointInterface</hardwareInterface> 
              <mechanicalReduction>1</mechanicalReduction>
        </actuator>
  </transmission>

  <transmission name="link_3_trans">
        <type>transmission_interface/SimpleTransmission</type>
        <joint name="joint_3">
              <hardwareInterface>hardware_interface/PositionJointInterface</hardwareInterface> 
        </joint>
        <actuator name="link_3_motor">
              <hardwareInterface>hardware_interface/PositionJointInterface</hardwareInterface> 
              <mechanicalReduction>1</mechanicalReduction>
        </actuator>
  </transmission>

  <transmission name="link_4_trans">
        <type>transmission_interface/SimpleTransmission</type>
        <joint name="joint_4">
              <hardwareInterface>hardware_interface/PositionJointInterface</hardwareInterface> 
        </joint>
        <actuator name="link_4_motor">
              <hardwareInterface>hardware_interface/PositionJointInterface</hardwareInterface> 
              <mechanicalReduction>1</mechanicalReduction>
        </actuator>
  </transmission>

  <transmission name="link_5_trans">
        <type>transmission_interface/SimpleTransmission</type>
        <joint name="joint_5">
              <hardwareInterface>hardware_interface/PositionJointInterface</hardwareInterface> 
        </joint>
        <actuator name="link_5_motor">
              <hardwareInterface>hardware_interface/PositionJointInterface</hardwareInterface> 
              <mechanicalReduction>1</mechanicalReduction>
        </actuator>
  </transmission>

  <transmission name="Right_ee_trans">
        <type>transmission_interface/SimpleTransmission</type>
        <joint name="joint_ree">
              <hardwareInterface>hardware_interface/PositionJointInterface</hardwareInterface> 
        </joint>
        <actuator name="Right_ee_motor">
              <hardwareInterface>hardware_interface/PositionJointInterface</hardwareInterface> 
              <mechanicalReduction>1</mechanicalReduction>
        </actuator>
  </transmission>

  <transmission name="Left_ee_trans">
        <type>transmission_interface/SimpleTransmission</type>
        <joint name="joint_lee">
              <hardwareInterface>hardware_interface/PositionJointInterface</hardwareInterface> 
        </joint>
        <actuator name="Left_ee_motor">
              <hardwareInterface>hardware_interface/PositionJointInterface</hardwareInterface> 
              <mechanicalReduction>1</mechanicalReduction>
        </actuator>
  </transmission>   

  <gazebo>
      <plugin name="control" filename="libgazebo_ros_control.so">
          <robotNamespace>/</robotNamespace>
      </plugin>
  </gazebo>

  <gazebo reference="rover">
      <selfCollide>true</selfCollide>
  </gazebo>

  <gazebo reference="base_arm">
      <selfCollide>true</selfCollide>
  </gazebo>

  <gazebo reference="link_1">
      <selfCollide>true</selfCollide>
  </gazebo>

  <gazebo reference="link_2">
      <selfCollide>true</selfCollide>
  </gazebo>

  <gazebo reference="link_3">
      <selfCollide>true</selfCollide>
  </gazebo>

  <gazebo reference="link_4">
      <selfCollide>true</selfCollide>
  </gazebo>

  <gazebo reference="link_5">
      <selfCollide>true</selfCollide>
  </gazebo>

  <gazebo reference="link_6">
      <selfCollide>true</selfCollide>
  </gazebo>

  <gazebo reference="Right_ee">
      <selfCollide>true</selfCollide>
  </gazebo>
  
  <gazebo reference="Left_ee">
      <selfCollide>true</selfCollide>
  </gazebo>

  <gazebo>
    <plugin name="gazebo_grasp_fix" filename="libgazebo_grasp_fix.so">
      <arm>
        <arm_name>/</arm_name>
        <palm_link>link_6</palm_link>
        <gripper_link>Right_ee</gripper_link>
        <gripper_link>Left_ee</gripper_link>
      </arm>
      <forces_angle_tolerance>90</forces_angle_tolerance>
      <update_rate>10</update_rate>
      <grip_count_threshold>3</grip_count_threshold>
      <max_grip_count>10</max_grip_count>
      <release_tolerance>0.004</release_tolerance>
      <disable_collisions_on_attach>true</disable_collisions_on_attach>
      <contact_topic>__default_topic__</contact_topic>
    </plugin> 
  </gazebo>

</robot>