<?xml version="1.0" encoding="utf-8"?>
<robot
  name="sampling_rover_with_arm_urdf">
  <link name="world"/>
  <joint name="base_rover" type="fixed">
      <parent link="world"/>
      <child link="rover"/>
      <origin rpy="0 0 0" xyz="0.0 0.0 0.00001"/>
  </joint>
  <link
    name="rover">
    <inertial>
      <origin
        xyz="0.04233 -0.030066 0.22201"
        rpy="0 0 0" />
      <mass
        value="23.83" />
      <inertia
        ixx="0.13598"
        ixy="0.0004091"
        ixz="0.0022915"
        iyy="0.10672"
        iyz="-0.0028185"
        izz="0.14333" />
    </inertial>
    <visual>
      <origin
        xyz="0 0 0"
        rpy="0 0 0" />
      <geometry>
        <mesh
          filename="package://sampling_rover_with_arm_urdf/meshes/rover.STL" />
      </geometry>
      <material
        name="">
        <color
          rgba="0.79216 0.81961 0.93333 1" />
      </material>
    </visual>
    <collision>
      <origin
        xyz="0 0 0"
        rpy="0 0 0" />
      <geometry>
        <mesh
          filename="package://sampling_rover_with_arm_urdf/meshes/rover.STL" />
      </geometry>
    </collision>
  </link>
  <link
    name="base_arm">
    <inertial>
      <origin
        xyz="7.5146E-16 1.2768E-15 0.062877"
        rpy="0 0 0" />
      <mass
        value="2.1128" />
      <inertia
        ixx="0.0074591"
        ixy="-6.4985E-07"
        ixz="2.9585E-17"
        iyy="0.0074553"
        iyz="-7.5664E-18"
        izz="0.010214" />
    </inertial>
    <visual>
      <origin
        xyz="0 0 0"
        rpy="0 0 0" />
      <geometry>
        <mesh
          filename="package://sampling_rover_with_arm_urdf/meshes/base_arm.STL" />
      </geometry>
      <material
        name="">
        <color
          rgba="0.79216 0.81961 0.93333 1" />
      </material>
    </visual>
    <collision>
      <origin
        xyz="0 0 0"
        rpy="0 0 0" />
      <geometry>
        <mesh
          filename="package://sampling_rover_with_arm_urdf/meshes/base_arm.STL" />
      </geometry>
    </collision>
  </link>
  <joint
    name="base_joint"
    type="fixed">
    <origin
      xyz="-0.00070858 0.2487 0.409"
      rpy="0 0 0" />
    <parent
      link="rover" />
    <child
      link="base_arm" />
    <axis
      xyz="0 0 0" />
    <limit
      lower="0"
      upper="0"
      effort="0"
      velocity="0" />
  </joint>
  <link
    name="link_1">
    <inertial>
      <origin
        xyz="0.00064135 -0.0059228 0.051415"
        rpy="0 0 0" />
      <mass
        value="0.49072" />
      <inertia
        ixx="0.001755"
        ixy="3.1435E-07"
        ixz="-7.1879E-07"
        iyy="0.0010881"
        iyz="0.00019759"
        izz="0.001162" />
    </inertial>
    <visual>
      <origin
        xyz="0 0 0"
        rpy="0 0 0" />
      <geometry>
        <mesh
          filename="package://sampling_rover_with_arm_urdf/meshes/link_1.STL" />
      </geometry>
      <material
        name="">
        <color
          rgba="0.89804 0.91765 0.92941 1" />
      </material>
    </visual>
    <collision>
      <origin
        xyz="0 0 0"
        rpy="0 0 0" />
      <geometry>
        <mesh
          filename="package://sampling_rover_with_arm_urdf/meshes/link_1.STL" />
      </geometry>
    </collision>
  </link>
  <joint
    name="joint_1"
    type="revolute">
    <origin
      xyz="0 0 0.131"
      rpy="0 0 0" />
    <parent
      link="base_arm" />
    <child
      link="link_1" />
    <axis
      xyz="0 0 1" />
    <limit
      lower="-3.142"
      upper="3.142"
      effort="100"
      velocity="2" />
  </joint>
  <link
    name="link_2">
    <inertial>
      <origin
        xyz="-3.148E-06 0.2843 0.0099169"
        rpy="0 0 0" />
      <mass
        value="1.1101" />
      <inertia
        ixx="0.0026516"
        ixy="-1.2212E-07"
        ixz="-1.1353E-07"
        iyy="0.0012227"
        iyz="-0.00020306"
        izz="0.0025953" />
    </inertial>
    <visual>
      <origin
        xyz="0 0 0"
        rpy="0 0 0" />
      <geometry>
        <mesh
          filename="package://sampling_rover_with_arm_urdf/meshes/link_2.STL" />
      </geometry>
      <material
        name="">
        <color
          rgba="0.79216 0.81961 0.93333 1" />
      </material>
    </visual>
    <collision>
      <origin
        xyz="0 0 0"
        rpy="0 0 0" />
      <geometry>
        <mesh
          filename="package://sampling_rover_with_arm_urdf/meshes/link_2.STL" />
      </geometry>
    </collision>
  </link>
  <joint
    name="joint_2"
    type="revolute">
    <origin
      xyz="0 -0.0355 0.1519"
      rpy="1.5708 0 -1.5708" />
    <parent
      link="link_1" />
    <child
      link="link_2" />
    <axis
      xyz="0 0 1" />
    <limit
      lower="-3.142"
      upper="3.142"
      effort="100"
      velocity="2" />
  </joint>
  <link
    name="link_3">
    <inertial>
      <origin
        xyz="2.2204E-16 0.0011125 -0.0037525"
        rpy="0 0 0" />
      <mass
        value="0.83444" />
      <inertia
        ixx="0.0013519"
        ixy="9.0993E-07"
        ixz="9.3162E-20"
        iyy="0.0013665"
        iyz="-1.2183E-05"
        izz="0.0015146" />
    </inertial>
    <visual>
      <origin
        xyz="0 0 0"
        rpy="0 0 0" />
      <geometry>
        <mesh
          filename="package://sampling_rover_with_arm_urdf/meshes/link_3.STL" />
      </geometry>
      <material
        name="">
        <color
          rgba="0.79216 0.81961 0.93333 1" />
      </material>
    </visual>
    <collision>
      <origin
        xyz="0 0 0"
        rpy="0 0 0" />
      <geometry>
        <mesh
          filename="package://sampling_rover_with_arm_urdf/meshes/link_3.STL" />
      </geometry>
    </collision>
  </link>
  <joint
    name="joint_3"
    type="revolute">
    <origin
      xyz="0 0.363 0.149"
      rpy="0 0 1.5708" />
    <parent
      link="link_2" />
    <child
      link="link_3" />
    <axis
      xyz="0 0 -1" />
    <limit
      lower="-3.142"
      upper="3.142"
      effort="50"
      velocity="4" />
  </joint>
  <link
    name="link_4">
    <inertial>
      <origin
        xyz="-0.0011125 -1.0547E-15 -0.0037525"
        rpy="0 0 0" />
      <mass
        value="0.83444" />
      <inertia
        ixx="0.0013665"
        ixy="-9.0993E-07"
        ixz="1.2183E-05"
        iyy="0.0013519"
        iyz="1.3053E-20"
        izz="0.0015146" />
    </inertial>
    <visual>
      <origin
        xyz="0 0 0"
        rpy="0 0 0" />
      <geometry>
        <mesh
          filename="package://sampling_rover_with_arm_urdf/meshes/link_4.STL" />
      </geometry>
      <material
        name="">
        <color
          rgba="0.79216 0.81961 0.93333 1" />
      </material>
    </visual>
    <collision>
      <origin
        xyz="0 0 0"
        rpy="0 0 0" />
      <geometry>
        <mesh
          filename="package://sampling_rover_with_arm_urdf/meshes/link_4.STL" />
      </geometry>
    </collision>
  </link>
  <joint
    name="joint_4"
    type="revolute">
    <origin
      xyz="0 0.13161 0.10761"
      rpy="-1.5708 0 0" />
    <parent
      link="link_3" />
    <child
      link="link_4" />
    <axis
      xyz="0 0 -1" />
    <limit
      lower="-3.142"
      upper="3.142"
      effort="50"
      velocity="4" />
  </joint>
  <link
    name="link_5">
    <inertial>
      <origin
        xyz="0.0056805 -0.00015103 -0.30906"
        rpy="0 0 0" />
      <mass
        value="1.0858" />
      <inertia
        ixx="0.001469"
        ixy="-1.5038E-06"
        ixz="7.5505E-06"
        iyy="0.0014597"
        iyz="-1.0158E-06"
        izz="0.002048" />
    </inertial>
    <visual>
      <origin
        xyz="0 0 0"
        rpy="0 0 0" />
      <geometry>
        <mesh
          filename="package://sampling_rover_with_arm_urdf/meshes/link_5.STL" />
      </geometry>
      <material
        name="">
        <color
          rgba="0.79216 0.81961 0.93333 1" />
      </material>
    </visual>
    <collision>
      <origin
        xyz="0 0 0"
        rpy="0 0 0" />
      <geometry>
        <mesh
          filename="package://sampling_rover_with_arm_urdf/meshes/link_5.STL" />
      </geometry>
    </collision>
  </link>
  <joint
    name="joint_5"
    type="revolute">
    <origin
      xyz="-0.45203 0 0.10768"
      rpy="-1.5708 0 1.5708" />
    <parent
      link="link_4" />
    <child
      link="link_5" />
    <axis
      xyz="0 0 -1" />
    <limit
      lower="-3.142"
      upper="3.142"
      effort="50"
      velocity="4" />
  </joint>
  <link
    name="Right_ee">
    <inertial>
      <origin
        xyz="0.011076 -0.16984 -0.00036022"
        rpy="0 0 0" />
      <mass
        value="0.15605" />
      <inertia
        ixx="0.0007532"
        ixy="1.5845E-05"
        ixz="-1.1744E-13"
        iyy="0.00044526"
        iyz="-2.7993E-13"
        izz="0.0004941" />
    </inertial>
    <visual>
      <origin
        xyz="0 0 0"
        rpy="0 0 0" />
      <geometry>
        <mesh
          filename="package://sampling_rover_with_arm_urdf/meshes/Right_ee.STL" />
      </geometry>
      <material
        name="">
        <color
          rgba="0.79216 0.81961 0.93333 1" />
      </material>
    </visual>
    <collision>
      <origin
        xyz="0 0 0"
        rpy="0 0 0" />
      <geometry>
        <mesh
          filename="package://sampling_rover_with_arm_urdf/meshes/Right_ee.STL" />
      </geometry>
    </collision>
  </link>
  <joint
    name="joint_ree"
    type="revolute">
    <origin
      xyz="0 0.03156 -0.18278"
      rpy="-1.5708 0 1.5708" />
    <parent
      link="link_5" />
    <child
      link="Right_ee" />
    <axis
      xyz="0 0 1" />
    <limit
      lower="0"
      upper="0.8"
      effort="15"
      velocity="6" />
  </joint>
  <link
    name="Left_ee">
    <inertial>
      <origin
        xyz="-0.011076 -0.16984 -0.00041022"
        rpy="0 0 0" />
      <mass
        value="0.15605" />
      <inertia
        ixx="0.0007532"
        ixy="-1.5845E-05"
        ixz="-1.1743E-13"
        iyy="0.00044526"
        iyz="2.7992E-13"
        izz="0.0004941" />
    </inertial>
    <visual>
      <origin
        xyz="0 0 0"
        rpy="0 0 0" />
      <geometry>
        <mesh
          filename="package://sampling_rover_with_arm_urdf/meshes/Left_ee.STL" />
      </geometry>
      <material
        name="">
        <color
          rgba="0.1098 0.1098 0.1098 1" />
      </material>
    </visual>
    <collision>
      <origin
        xyz="0 0 0"
        rpy="0 0 0" />
      <geometry>
        <mesh
          filename="package://sampling_rover_with_arm_urdf/meshes/Left_ee.STL" />
      </geometry>
    </collision>
  </link>
  <joint
    name="joint_lee"
    type="revolute">
    <origin
      xyz="0 -0.031415 -0.18278"
      rpy="-1.5708 0 1.5708" />
    <parent
      link="link_5" />
    <child
      link="Left_ee" />
    <axis
      xyz="0 0 1" />
    <limit
      lower="-0.8"
      upper="0"
      effort="15"
      velocity="6" />
  </joint>
  
  <transmission name="link_1_trans">
    <type>transmission_interface/SimpleTransmission</type>
    <joint name="joint_1">
      <hardwareInterface>hardware_interface/PositionJointInterface</hardwareInterface> 
    </joint>
    <actuator name="link_1_motor">
      <hardwareInterface>hardware_interface/PositionJointInterface</hardwareInterface> 
      <mechanicalReduction>1</mechanicalReduction>
    </actuator>
  </transmission>

  <transmission name="link_2_trans">
    <type>transmission_interface/SimpleTransmission</type>
    <joint name="joint_2">
      <hardwareInterface>hardware_interface/PositionJointInterface</hardwareInterface> 
    </joint>
    <actuator name="link_2_motor">
      <hardwareInterface>hardware_interface/PositionJointInterface</hardwareInterface> 
      <mechanicalReduction>1</mechanicalReduction>
    </actuator>
  </transmission>

  <transmission name="link_3_trans">
    <type>transmission_interface/SimpleTransmission</type>
    <joint name="joint_3">
      <hardwareInterface>hardware_interface/PositionJointInterface</hardwareInterface> 
    </joint>
    <actuator name="link_3_motor">
      <hardwareInterface>hardware_interface/PositionJointInterface</hardwareInterface> 
      <mechanicalReduction>1</mechanicalReduction>
    </actuator>
  </transmission>

  <transmission name="link_4_trans">
    <type>transmission_interface/SimpleTransmission</type>
    <joint name="joint_4">
      <hardwareInterface>hardware_interface/PositionJointInterface</hardwareInterface> 
    </joint>
    <actuator name="link_4_motor">
      <hardwareInterface>hardware_interface/PositionJointInterface</hardwareInterface> 
      <mechanicalReduction>1</mechanicalReduction>
    </actuator>
  </transmission>

  <transmission name="link_5_trans">
    <type>transmission_interface/SimpleTransmission</type>
    <joint name="joint_5">
      <hardwareInterface>hardware_interface/PositionJointInterface</hardwareInterface> 
    </joint>
    <actuator name="link_5_motor">
      <hardwareInterface>hardware_interface/PositionJointInterface</hardwareInterface> 
      <mechanicalReduction>1</mechanicalReduction>
    </actuator>
  </transmission>

  <transmission name="Right_ee_trans">
    <type>transmission_interface/SimpleTransmission</type>
    <joint name="joint_ree">
      <hardwareInterface>hardware_interface/PositionJointInterface</hardwareInterface> 
    </joint>
    <actuator name="Right_ee_motor">
      <hardwareInterface>hardware_interface/PositionJointInterface</hardwareInterface> 
      <mechanicalReduction>1</mechanicalReduction>
    </actuator>
  </transmission>

  <transmission name="Left_ee_trans">
    <type>transmission_interface/SimpleTransmission</type>
    <joint name="joint_lee">
      <hardwareInterface>hardware_interface/PositionJointInterface</hardwareInterface> 
    </joint>
    <actuator name="Left_ee_motor">
      <hardwareInterface>hardware_interface/PositionJointInterface</hardwareInterface> 
      <mechanicalReduction>1</mechanicalReduction>
    </actuator>
  </transmission>   

  <gazebo>
    <plugin name="control" filename="libgazebo_ros_control.so">
      <robotNamespace>/</robotNamespace>
    </plugin>
  </gazebo>

  <gazebo reference="rover">
      <selfCollide>true</selfCollide>
  </gazebo>

  <gazebo reference="base_arm">
      <selfCollide>true</selfCollide>
  </gazebo>

  <gazebo reference="link_1">
      <selfCollide>true</selfCollide>
  </gazebo>

  <gazebo reference="link_2">
      <selfCollide>true</selfCollide>
  </gazebo>

  <gazebo reference="link_3">
      <selfCollide>true</selfCollide>
  </gazebo>

  <gazebo reference="link_4">
      <selfCollide>true</selfCollide>
  </gazebo>

  <gazebo reference="link_5">
      <selfCollide>true</selfCollide>
  </gazebo>

  <gazebo reference="Right_ee">
      <selfCollide>true</selfCollide>
  </gazebo>
  
  <gazebo reference="Left_ee">
      <selfCollide>true</selfCollide>
  </gazebo>

   

   <link name="camera_link2">
    <inertial>
      <mass value="0.001"/>
      <inertia ixx="0.0001" ixy="0.0" ixz="0.0" iyy="0.0001" iyz="0.0" izz="0.0001"/>
    </inertial>
    <visual>
      <origin xyz="0 0 0" rpy="0 0 0"/>
      <geometry>
        <box size="0.01 0.01 0.01"/>
      </geometry>
      <material name="camera_material">
        <color rgba="0.0 0.0 1.0 1.0"/>
      </material>
    </visual>
  </link>

  <joint name="camera_depth_optical_joint" type="fixed">
    <origin xyz="0 0 0" rpy="-1.57079632679 0 -1.57079632679" />
    <parent link="camera_link2" />
    <child link="camera_depth_optical_frame" />
  </joint>

  <joint name="camera_joint2" type="fixed">
    <origin xyz="0 0.3 0.35" rpy="0 0 1.57079632679" /> 
    <parent link="rover" />
    <child link="camera_link2" />
  </joint>

  <link name="camera_depth_optical_frame">
    <inertial>
      <mass value="0.001"/>
      <inertia ixx="0.0001" ixy="0.0" ixz="0.0" iyy="0.0001" iyz="0.0" izz="0.0001"/>
    </inertial>
  </link>      

  <gazebo reference="camera_link2">
    <sensor type="depth" name="camera2">
      <pose>0 0 0 0 0 0</pose>
      <visualize>true</visualize>
      <update_rate>15.0</update_rate>
      <camera name="camera2">
        <horizontal_fov>1.7633</horizontal_fov>
        <image>
          <width>1280</width>
          <height>720</height>
          <format>R8G8B8</format>
        </image>
        <clip>
          <near>0.02</near>
          <far>300</far>
        </clip>
        <noise>
          <type>gaussian</type>
          <mean>0.0</mean>
          <stddev>0.007</stddev>
        </noise>
      </camera>
      <plugin name="camera_plugin" filename="libgazebo_ros_depth_camera.so">
        <always_on>true</always_on>
        <update_rate>0.0</update_rate>
        <frameName>camera_depth_optical_frame2</frameName>
        <pointCloudCutoff>0.3</pointCloudCutoff>
        <pointCloudCutoffMax>20</pointCloudCutoffMax>
        <imageTopicName>/camera/color/image_raw2</imageTopicName>
        <cameraInfoTopicName>/camera/color/camera_info2</cameraInfoTopicName>
        <depthImageTopicName>/camera/depth/image_raw2</depthImageTopicName>
        <depthImageCameraInfoTopicName>/camera/depth/camera_info2</depthImageCameraInfoTopicName>
        <pointCloudTopicName>/camera/depth/points2</pointCloudTopicName>
        <distortionK1>-0.040993299</distortionK1>
        <distortionK2>0.009593590</distortionK2>
        <distortionT1>-0.004429849</distortionT1>
        <distortionT2>0.000192024</distortionT2>
        <distortionK3>-0.000320880</distortionK3>
        <CxPrime>659.3049926757812</CxPrime>
        <Cx>659.3049926757812</Cx>
        <Cy>371.39849853515625</Cy>
        <hackBaseline>0.12</hackBaseline>
      </plugin>
    </sensor>
  </gazebo>



  <link name="camera_link1">
    <inertial>
      <mass value="0.001"/>
      <inertia ixx="0.0001" ixy="0.0" ixz="0.0" iyy="0.0001" iyz="0.0" izz="0.0001"/>
    </inertial>
    <visual>
      <origin xyz="0 0 0" rpy="0 0 0"/>
      <geometry>
        <box size="0.01 0.01 0.01"/>
      </geometry>
      <material name="camera_material">
        <color rgba="0.0 0.0 1.0 1.0"/>
      </material>
    </visual>
  </link>
      
  <joint name="camera_joint1" type="fixed">
    <origin xyz="0.12 0.0 -0.3" rpy="-3.1412 -1.57079632679 0" /> 
    <parent link="link_5" />
    <child link="camera_link1" />
  </joint>


  <gazebo reference="camera_link1">
    <sensor type="depth" name="camera1">
      <pose>0 0 0 0 0 0</pose>
      <visualize>true</visualize>
      <update_rate>15.0</update_rate>
      <camera name="camera1">
        <horizontal_fov>1.7633</horizontal_fov>
        <image>
          <width>1280</width>
          <height>720</height>
          <format>R8G8B8</format>
        </image>
        <clip>
          <near>0.02</near>
          <far>300</far>
        </clip>
        <noise>
          <type>gaussian</type>
          <mean>0.0</mean>
          <stddev>0.007</stddev>
        </noise>
      </camera>
      <plugin name="camera_plugin" filename="libgazebo_ros_depth_camera.so">
        <always_on>true</always_on>
        <update_rate>0.0</update_rate>
        <frameName>camera_depth_optical_frame1</frameName>
        <pointCloudCutoff>0.3</pointCloudCutoff>
        <pointCloudCutoffMax>20</pointCloudCutoffMax>
        <imageTopicName>/camera/color/image_raw1</imageTopicName>
        <cameraInfoTopicName>/camera/color/camera_info1</cameraInfoTopicName>
        <depthImageTopicName>/camera/depth/image_raw1</depthImageTopicName>
        <depthImageCameraInfoTopicName>/camera/depth/camera_info1</depthImageCameraInfoTopicName>
        <pointCloudTopicName>/camera/depth/points1</pointCloudTopicName>
        <distortionK1>-0.040993299</distortionK1>
        <distortionK2>0.009593590</distortionK2>
        <distortionT1>-0.004429849</distortionT1>
        <distortionT2>0.000192024</distortionT2>
        <distortionK3>-0.000320880</distortionK3>
        <CxPrime>659.3049926757812</CxPrime>
        <Cx>659.3049926757812</Cx>
        <Cy>371.39849853515625</Cy>
        <hackBaseline>0.12</hackBaseline>
      </plugin>
    </sensor>
  </gazebo>

  
</robot>